---
title: 消除异步函数的传染性
editLink: true
prev:
text: '消除异步函数的传染性'
link: '/articles/消除异步函数的传染性'
---

# {{ $frontmatter.title }}

消除异步函数的传染性

```javascript

// 定义一个执行函数
function eliminateAsync(func, asyncFunc) {
  let i = 0;
  let cache = []; // 用于缓存数据
  let _originMain = asyncFunc; // 把异步函数赋值到一个变量供后面执行
  // 定义一个回调函数，这个函数会在异步函数执行完毕后执行
  const callbackFunc = (...arg) => {
    // 重新定义异步函数
    // 判断缓存中有没有数据，第一次肯定没有
    if (cache[i]) {
      // 如果有缓存数据
      // 如果状态是fulfilled的，就返回缓存数据
      if (cache[i].status === "fulfilled") {
        console.log(...arg, "参数");
        return cache[i].data;
      } else {
        // 如果异步函数执行错误了就返回错误信息
        return cache[i].error;
      }
    }
    let result = {
      status: "pending",
      data: null,
      error: null,
    };
    // 保存缓存信息，第一次缓存数据是假缓存
    cache[i++] = result;
    // 执行一函数，第一次不等待函数执行完，执行下面的抛出错误 throw pro
    let pro = _originMain(...arg).then(
      (resp) => {
        // 把数据缓存起来
        result.status = "fulfilled";
        result.data = resp;
      },
      (err) => {
        // 把错误数据缓存起来
        result.status = "rejected";
        result.error = err;
      }
    );
    // 抛出错误，这里抛出的错误是一个promise对象，因为我们在执行异步函数的时候
    throw pro;
  };
  try {
    func(callbackFunc);
  } catch (err) {
    if (err instanceof Promise) {
      // 如果抛出的错误是一个promise对象，就执行下面的代码
      const reRun = () => {
        // 重新执行传进来的函数 并且把i重置为0
        i = 0;
        func(callbackFunc);
      };
      // 接收到抛出的错误后，再等待异步函数执行完成后重新运行传进来的函数，下次运行
      // 就能拿到缓存的数据了，因为异步函数已经执行完毕，缓存已经保存了
      err.then(reRun, reRun);
    }
  }
}
function asyncFunc() {
  return new Promise((resolve, reject) => {
    setTimeout(() => {
      resolve("收到反馈和案说法");
    }, 10000);
  });
}
function f1(callbackFunc) {
  console.log(11); // 其实你会发现这个打印执行了2次，明白其中道理就会知道为什么会打印2次
  const user = callbackFunc("aaaaaaa");
  console.log(user, "111111111111111");
}

eliminateAsync(f1, asyncFunc); // 一秒过后打印 ‘收到数据并返回信息’


```